<?xml version="1.0"?>
<sdf version="1.6">
  <model name="puzzlebot" canonical_link="chassis">
    <static>false</static>
    <!--chassis-->
    <link name='chassis'>
      <pose relative_to='__model__'>0 0 0.05 0 0 0</pose>
      <inertial>
        <mass>0.8</mass>
        <pose>-0.05 0 0 0 0 0</pose>
        <inertia>
          <ixx>0.004</ixx>
          <iyy>0.004</iyy>
          <izz>0.004</izz>
          <ixy>0</ixy>
          <ixz>0</ixz>
          <iyz>0</iyz>
        </inertia>
      </inertial>
      <visual name='visual'>
        <geometry>
          <mesh>
            <uri>file:///home/idmx/ros2_ws_2/src/motor_control/puzzlebot/meshes/chassis1.dae</uri>
          </mesh>
        </geometry>
      </visual>
      <collision name='collision'>
        <pose>-0.055 0 0 0 0 0</pose>
        <geometry>
          <box>
            <size>0.2 0.16 0.046</size>
          </box>
        </geometry>
      </collision>
    </link>

    <!--Right wheel-->
    <link name='right_wheel'>
      <pose relative_to="chassis">0.0 -0.095 0 0 0 3.1415</pose>
      <inertial>
        <mass>0.05</mass>
        <inertia>
          <ixx>0.002</ixx>
          <iyy>0.002</iyy>
          <izz>0.002</izz>
          <ixy>0</ixy>
          <ixz>0</ixz>
          <iyz>0</iyz>
        </inertia>
      </inertial>
      <visual name='visual'>
        <geometry>
          <mesh>
            <uri>file:///home/idmx/ros2_ws_2/src/motor_control/puzzlebot/meshes/wheel.dae</uri>
          </mesh>
        </geometry>
      </visual>
      <collision name='collision'>
        <pose>0 -0.0025 0 1.5707 0 0</pose>
        <geometry>
          <cylinder>
            <radius>0.05</radius>
            <length>0.005</length>
          </cylinder>
        </geometry>
        <surface>
          <friction>
            <ode>
              <mu>1.0</mu>
              <mu2>1.0</mu2>
            </ode>
          </friction>
        </surface>
      </collision>
    </link>

    <!--Left wheel-->
    <link name='left_wheel'>
      <pose relative_to="chassis">0.0 0.095 0 0 0 0</pose>
      <inertial>
        <mass>0.05</mass>
        <inertia>
          <ixx>0.002</ixx>
          <iyy>0.002</iyy>
          <izz>0.002</izz>
          <ixy>0</ixy>
          <ixz>0</ixz>
          <iyz>0</iyz>
        </inertia>
      </inertial>
      <visual name='visual'>
        <geometry>
          <mesh>
            <uri>file:///home/idmx/ros2_ws_2/src/motor_control/puzzlebot/meshes/wheel.dae</uri>
          </mesh>
        </geometry>
      </visual>
      <collision name='collision'>
        <pose>0 -0.0025 0 1.5707 0 0</pose>
        <geometry>
          <cylinder>
            <radius>0.05</radius>
            <length>0.005</length>
          </cylinder>
        </geometry>
        <surface>
          <friction>
            <ode>
              <mu>1.0</mu>
              <mu2>1.0</mu2>
            </ode>
          </friction>
        </surface>
      </collision>
    </link>

    <!--arbitrary frame-->
    <frame name="caster_frame" attached_to='chassis'>
      <pose>-0.145 0 -0.044 0 0 0</pose>
    </frame>

    <!--caster wheel-->
    <link name='caster'>
      <pose relative_to='caster_frame'/>
      <inertial>
        <mass>0.01</mass>
        <inertia>
          <ixx>0.0000025</ixx>
          <iyy>0.0000025</iyy>
          <izz>0.0000025</izz>
          <ixy>0</ixy>
          <ixz>0</ixz>
          <iyz>0</iyz>
        </inertia>
      </inertial>
      <visual name='visual'>
        <geometry>
          <sphere>
            <radius>0.006</radius>
          </sphere>
        </geometry>
        <material>
          <ambient>0.0 1 0.0 1</ambient>
          <diffuse>0.0 1 0.0 1</diffuse>
          <specular>0.0 1 0.0 1</specular>
        </material>
      </visual>
      <collision name='collision'>
        <geometry>
          <sphere>
            <radius>0.006</radius>
          </sphere>
        </geometry>
      </collision>
    </link>

    <!--left wheel joint-->
    <joint name='left_wheel_joint' type='revolute'>
      <pose relative_to='left_wheel'/>
      <parent>chassis</parent>
      <child>left_wheel</child>
      <axis>
        <xyz expressed_in='__model__'>0 1 0</xyz>
        <limit>
          <lower>-1.79769e+308</lower>
          <upper>1.79769e+308</upper>
          <effort>50</effort>
        </limit>
        <dynamics>
          <friction>0.1</friction>
        </dynamics>
      </axis>
    </joint>

    <!--right wheel joint-->
    <joint name='right_wheel_joint' type='revolute'>
      <pose relative_to='right_wheel'/>
      <parent>chassis</parent>
      <child>right_wheel</child>
      <axis>
        <xyz expressed_in='__model__'>0 1 0</xyz>
        <limit>
          <lower>-1.79769e+308</lower>
          <upper>1.79769e+308</upper>
          <effort>50</effort>
        </limit>
        <dynamics>
          <friction>0.1</friction>
        </dynamics>
      </axis>
    </joint>

    <!--caster wheel joint-->
    <joint name='caster_wheel' type='ball'>
      <parent>chassis</parent>
      <child>caster</child>
    </joint>

    <!-- Puzzlebot differential drive plugin para Gazebo Garden -->
    <plugin name="gz::sim::systems::DiffDrive" filename="libgz-sim-diff-drive-system.so">
      <left_joint>left_wheel_joint</left_joint>
      <right_joint>right_wheel_joint</right_joint>
      <wheel_separation>0.19</wheel_separation>
      <wheel_radius>0.05</wheel_radius>
      <topic>/cmd_vel</topic>
      <odom_topic>/odom_sim</odom_topic>
      <robot_base_frame>chassis</robot_base_frame>
      <odometry_frame>odom</odometry_frame>
      <publish_odom>true</publish_odom>
    </plugin>

  </model>
</sdf>
